# Core文件分析报告 - VecTest.cc崩溃分析

## 崩溃基本信息

### 崩溃信号
- **信号类型**: `SIGABRT` (信号6)
- **程序**: `./VecTest`
- **进程ID**: 10034
- **线程数**: 3个线程 (LWP 10034, 10036, 10037)

### 崩溃位置
```
#0  __pthread_kill_implementation (no_tid=0, signo=6, threadid=129176166196800) 
    at ./nptl/pthread_kill.c:44
```

## 问题分析

### 1. SIGABRT信号的含义
`SIGABRT` 信号通常由以下原因触发：
- **断言失败** (`assert()` 失败)
- **内存分配失败** (`malloc`, `new` 失败)
- **C++异常未捕获**
- **程序主动调用 `abort()`**

### 2. 多线程并发问题
从core文件可以看到3个线程：
- **主线程** (LWP 10034)
- **修改线程1** (LWP 10036) 
- **修改线程2** (LWP 10037)

### 3. 可能的问题场景

#### 场景A：内存分配失败
```cpp
// 当vector扩容时，如果内存分配失败
unsafe_vec.push_back(i);  // 可能抛出std::bad_alloc
```

#### 场景B：C++异常未捕获
```cpp
// vector操作可能抛出异常
// 但程序没有try-catch块
```

#### 场景C：断言失败
```cpp
// 某些STL实现可能有内部断言
// 检测到数据竞争时触发
```

## 深入调试步骤

### 步骤1：查看完整调用栈
```gdb
(gdb) bt
(gdb) thread apply all bt
```

### 步骤2：检查vector状态
```gdb
(gdb) print unsafe_vec
(gdb) print unsafe_vec.size()
(gdb) print unsafe_vec.capacity()
```

### 步骤3：检查内存布局
```gdb
(gdb) x/3gx &unsafe_vec
```

### 步骤4：检查异常信息
```gdb
(gdb) info signal
(gdb) catch throw
```

## 解决方案

### 1. 添加异常处理
```cpp
try {
    unsafe_vec.push_back(i);
} catch (const std::exception& e) {
    std::cerr << "Exception: " << e.what() << std::endl;
}
```

### 2. 使用线程安全容器
```cpp
#include <mutex>
std::mutex vec_mutex;
std::lock_guard<std::mutex> lock(vec_mutex);
unsafe_vec.push_back(i);
```

### 3. 检查内存限制
```bash
# 检查系统内存
free -h
# 检查进程内存限制
ulimit -a
```

## 预防措施

1. **启用异常处理**: 编译时使用 `-fexceptions`
2. **内存检查**: 使用 `valgrind` 或 `AddressSanitizer`
3. **线程检查**: 使用 `ThreadSanitizer`
4. **日志记录**: 添加详细的错误日志

## 编译建议

```bash
# 启用所有调试信息
g++ -g -O0 -std=c++11 -pthread -fexceptions VecTest.cc -o VecTest

# 启用地址消毒器
g++ -g -O0 -std=c++11 -pthread -fsanitize=address VecTest.cc -o VecTest

# 启用线程消毒器
g++ -g -O0 -std=c++11 -pthread -fsanitize=thread VecTest.cc -o VecTest
```

## 下一步调试

1. 使用GDB脚本分析core文件
2. 检查是否有未捕获的C++异常
3. 验证内存分配是否成功
4. 分析线程间的数据竞争 